<?xml version="1.0"?>
<robot name="my_robot">
  
  <material name="green">
    <color rgba="0.0 0.5 0.0 1.0" />
  </material>

  <material name="Cyan">
    <color rgba="0 1.0 1.0 1.0"/>
  </material>

  <link name="base_link">
    <visual>
      <geometry>
        <!-- long width height -->
        <box size="0.6 0.4 0.2" />
      </geometry>
      <!-- rpy: roll pitch yaw, rotaion on  x, y, z axis -->
      <origin xyz="0 0 0.1 " rpy="0 0 0" />
      <material name="Cyan"/>
    </visual>
  </link>

  <link name="second_link">
    <visual>
      <geometry>
        <cylinder radius="0.1" length="0.2" />
      </geometry>
      <origin xyz="0 0 0.1" rpy="0 0 0" />
      <material name="green" />
    </visual>
  </link>

  <joint name="base_second_joint" type="revolute">
    <parent link="base_link" />
    <child link="second_link"/>
    <origin xyz="0 0 0.2" rpy="0 0 0"/>
    <axis xyz="0 0 1" />
    <limit lower="-1.57" upper="1.57" velocity="100" effort="100" />
    <!-- pi = 180 = 3.14 -->
   </joint>

</robot>